Workbook

Sheet AllocEntry for Actng(truncated)
D2: Adobe Cost Allocation per Month
A3: CCID - order of pulling data: 1. cost centers vlookup to HR home cost center, 2. prior version and 3. user group if undetermined by the 1st 2 process | B3: Cost center description per CCID # | C3: Sum of # of Paid License Holder | D3: Sum of TOTAL Cost
A4: CC001 | B4: USA - Stack - Seattle - Operations | C4: 13 | D4: 175.06333
A5: CC004 | B5: USA - Stack - Antioch - Operations | C5: 11 | D5: 152.03167
A6: CC005 | B6: USA - Stack - Antioch - G&A | C6: 2 | D6: 23.031667
A7: CC007 | B7: USA - Stack - Santa Ana - Operations | C7: 22 | D7: 287.15833
A8: CC008 | B8: USA - Stack - Santa Ana - G&A | C8: 2 | D8: 17.396667
A9: CC010 | B9: USA - Stack - Gulf Coast - Operations | C9: 8 | D9: 109.03167
A10: CC011 | B10: USA - Stack - Gulf Coast - G&A | C10: 6 | D10: 86
A11: CC013 | B11: USA - Stack - Great Plains - Operations | C11: 3 | D11: 37.365
A12: CC014 | B12: USA - Stack - Great Plains - G&A | C12: 2 | D12: 28.666667
A13: CC016 | B13: USA - Stack - Southeast - Operations | C13: 10 | D13: 143.33333
A14: CC017 | B14: USA - Stack - Southeast - G&A | C14: 1 | D14: 14.333333
A15: CC019 | B15: USA - Stack - Chicago - Operations | C15: 11 | D15: 135.12667
... A143: CC478 | B143: USA - Corp - IT Management | C143: 1 | D143: 14.333333
A144: (blank) | B144: (blank) | D144: 0
A145: Grand Total | C145: 1103 | D145: 16336.833 | E145: Credit USA Corp IT Operations under Computer Software

Sheet Allocation Details by Lic Type
A3: CCID - order of pulling data: 1. cost centers vlookup to HR home cost center, 2. prior version and 3. user group if undetermined by the 1st 2 process | B3: Cost center description per CCID # | C3: Product Configurations 1 | D3: Product Configurations 2 | E3: Product Configurations 3 | F3: Sum of # of Paid License Holder | G3: Sum of TOTAL Cost
A4: CC001 | B4: USA - Stack - Seattle - Operations | C4: Default Acrobat Pro configuration | D4: (blank) | E4: (blank) | F4: 11 | G4: 157.66667
A5: CC001 | B5: USA - Stack - Seattle - Operations | C5: Default Acrobat Standard DC configuration | D5: (blank) | E5: (blank) | F5: 2 | G5: 17.396667
A6: CC004 | B6: USA - Stack - Antioch - Operations | C6: Default Acrobat Pro configuration | D6: (blank) | E6: (blank) | F6: 10 | G6: 143.33333
A7: CC004 | B7: USA - Stack - Antioch - Operations | C7: Default Acrobat Standard DC configuration | D7: (blank) | E7: (blank) | F7: 1 | G7: 8.6983333
A8: CC005 | B8: USA - Stack - Antioch - G&A | C8: Default Acrobat Pro configuration | D8: (blank) | E8: (blank) | F8: 1 | G8: 14.333333
A9: CC005 | B9: USA - Stack - Antioch - G&A | C9: Default Acrobat Standard DC configuration | D9: (blank) | E9: (blank) | F9: 1 | G9: 8.6983333
A10: CC007 | B10: USA - Stack - Santa Ana - Operations | C10: Default Acrobat Pro configuration | D10: (blank) | E10: (blank) | F10: 17 | G10: 243.66667
A11: CC007 | B11: USA - Stack - Santa Ana - Operations | C11: Default Acrobat Standard DC configuration | D11: (blank) | E11: (blank) | F11: 5 | G11: 43.491667
A12: CC008 | B12: USA - Stack - Santa Ana - G&A | C12: Default Acrobat Standard DC configuration | D12: (blank) | E12: (blank) | F12: 2 | G12: 17.396667
A13: CC010 | B13: USA - Stack - Gulf Coast - Operations | C13: Default Acrobat Pro configuration | D13: (blank) | E13: (blank) | F13: 7 | G13: 100.33333
A14: CC010 | B14: USA - Stack - Gulf Coast - Operations | C14: Default Acrobat Standard DC configuration | D14: (blank) | E14: (blank) | F14: 1 | G14: 8.6983333
A15: CC011 | B15: USA - Stack - Gulf Coast - G&A | C15: Default Acrobat Pro configuration | D15: (blank) | E15: (blank) | F15: 6 | G15: 86
... A236: CC478 | B236: USA - Corp - IT Management | C236: Default Acrobat Pro configuration | D236: (blank) | E236: (blank) | F236: 1 | G236: 14.333333
A237: (blank) | B237: (blank) | C237: Default All Apps - Edition 4 configuration | D237: (blank) | E237: (blank) | G237: 0
A238: Grand Total | F238: 1103 | G238: 16336.833

Sheet Adobe users (3)
A1: Identity Type | B1: Username | C1: Domain | D1: Email | E1: First Name | F1: Last Name | G1: Country Code | H1: ID | I1: Product Configurations 1 | J1: Product Configurations 2 | K1: Product Configurations 3 | L1: Admin Roles | M1: Product Configurations Administered | N1: User Groups | O1: User Groups Administered | P1: Products Administered | Q1: Contracts Administered | R1: Team Products | S1: Enterprise Products | T1: Developer Access | U1: Auto Assigned Products | V1: CCID - order of pulling data: 1. cost centers vlookup to HR home cost center, 2. prior version and 3. user group if undetermined by the 1st 2 process | W1: Cost center description per CCID # | X1: Product Configurations 1 - COST | Y1: Product Configurations 2 - COST | Z1: Product Configurations 3 - COST | AA1: TOTAL Cost | AB1: # of Paid License Holder
A2: Adobe ID | B2: mcarlin@montrose-env.com | C2: montrose-env.com | D2: mcarlin@montrose-env.com | E2: Mark | F2: Carlin | G2: US | H2: 038E2AA263C9DEEB0A495FEA@038d2aa263c9deeb495fea.e | L2: System | N2: USA - Corp - IT | X2: =IFERROR(VLOOKUP(I2,'Rate Sheet'!$D:$F,3,FALSE),0) -> 0 | Y2: =IFERROR(VLOOKUP(J2,'Rate Sheet'!$D:$F,3,FALSE),0) -> 0 | Z2: =IFERROR(VLOOKUP(K2,'Rate Sheet'!$D:$F,3,FALSE),0) -> 0 | AA2: =SUM(X2:Z2) -> 0
A3: Adobe ID | B3: grant.wicker@enthalpy.com | C3: enthalpy.com | D3: grant.wicker@enthalpy.com | E3: Grant | F3: Wicker | G3: US | H3: 04172ACB63C9DF460A495E05@038d2aa263c9deeb495fea.e | N3: USA - Corp - IT | X3: =IFERROR(VLOOKUP(I3,'Rate Sheet'!$D:$F,3,FALSE),0) -> 0 | Y3: =IFERROR(VLOOKUP(J3,'Rate Sheet'!$D:$F,3,FALSE),0) -> 0 | Z3: =IFERROR(VLOOKUP(K3,'Rate Sheet'!$D:$F,3,FALSE),0) -> 0 | AA3: =SUM(X3:Z3) -> 0
A4: Federated ID | B4: stescamilla@montrose-env.com | C4: montrose-env.com | D4: stescamilla@montrose-env.com | E4: Stacey | F4: Escamilla | G4: US | H4: C7E825EB63D846A50A495C5B@038d2aa263c9deeb495fea.e | N4: USA - Environmental Consulting - Environmental Intelligence - Operations | X4: =IFERROR(VLOOKUP(I4,'Rate Sheet'!$D:$F,3,FALSE),0) -> 0 | Y4: =IFERROR(VLOOKUP(J4,'Rate Sheet'!$D:$F,3,FALSE),0) -> 0 | Z4: =IFERROR(VLOOKUP(K4,'Rate Sheet'!$D:$F,3,FALSE),0) -> 0 | AA4: =SUM(X4:Z4) -> 0
A5: Federated ID | B5: mcarlinadmin@montrose-env.com | C5: montrose-env.com | D5: mcarlinadmin@montrose-env.com | E5: Mark | F5: Carlin Admin | G5: US | H5: C5DE265363D849620A495FDA@038d2aa263c9deeb495fea.e | L5: System | N5: USA - Corp - IT | X5: =IFERROR(VLOOKUP(I5,'Rate Sheet'!$D:$F,3,FALSE),0) -> 0 | Y5: =IFERROR(VLOOKUP(J5,'Rate Sheet'!$D:$F,3,FALSE),0) -> 0 | Z5: =IFERROR(VLOOKUP(K5,'Rate Sheet'!$D:$F,3,FALSE),0) -> 0 | AA5: =SUM(X5:Z5) -> 0
A6: Federated ID | B6: sbagchi@montrose-env.com | C6: montrose-env.com | D6: sbagchi@montrose-env.com | E6: Sohini | F6: Bagchi | G6: US | H6: C67F262A63D866EF0A495CA0@038d2aa263c9deeb495fea.e | I6: Default Acrobat Pro configuration | N6: USA - Environmental Consulting - Santa Ana (Rem) - Operations | S6: Acrobat Pro (VIPMP - 99C0A3088A102BD9CB4A) | V6: CC109 | W6: USA - Consulting - Santa Ana (Rem) - Operations | X6: =IFERROR(VLOOKUP(I6,'Rate Sheet'!$D:$F,3,FALSE),0) -> 14.333333 | Y6: =IFERROR(VLOOKUP(J6,'Rate Sheet'!$D:$F,3,FALSE),0) -> 0 | Z6: =IFERROR(VLOOKUP(K6,'Rate Sheet'!$D:$F,3,FALSE),0) -> 0 | AA6: =SUM(X6:Z6) -> 14.333333 | AB6: 1
A7: Federated ID | B7: lwork@montrose-env.com | C7: montrose-env.com | D7: lwork@montrose-env.com | E7: Lydia | F7: Work | G7: US | H7: 08EB268D63DA6A030A495FB1@038d2aa263c9deeb495fea.e | I7: Default Acrobat Pro configuration | N7: USA - Environmental Consulting - Valley Forge - Operations | S7: Acrobat Pro (VIPMP - 99C0A3088A102BD9CB4A) | V7: CC343 | W7: USA - Consulting - Valley Forge - Operations | X7: =IFERROR(VLOOKUP(I7,'Rate Sheet'!$D:$F,3,FALSE),0) -> 14.333333 | Y7: =IFERROR(VLOOKUP(J7,'Rate Sheet'!$D:$F,3,FALSE),0) -> 0 | Z7: =IFERROR(VLOOKUP(K7,'Rate Sheet'!$D:$F,3,FALSE),0) -> 0 | AA7: =SUM(X7:Z7) -> 14.333333 | AB7: 1
A8: Federated ID | B8: ligordon@montrose-env.com | C8: montrose-env.com | D8: ligordon@montrose-env.com | E8: Lindsey | F8: Gordon | G8: US | H8: 1039261B63DA8F350A495FED@038d2aa263c9deeb495fea.e | I8: Default Acrobat Pro configuration | N8: USA - Environmental Consulting - Environmental Intelligence - Operations | S8: Acrobat Pro (VIPMP - 99C0A3088A102BD9CB4A) | V8: CC272 | W8: USA - Consulting - Environmental Intelligence - Operations | X8: =IFERROR(VLOOKUP(I8,'Rate Sheet'!$D:$F,3,FALSE),0) -> 14.333333 | Y8: =IFERROR(VLOOKUP(J8,'Rate Sheet'!$D:$F,3,FALSE),0) -> 0 | Z8: =IFERROR(VLOOKUP(K8,'Rate Sheet'!$D:$F,3,FALSE),0) -> 0 | AA8: =SUM(X8:Z8) -> 14.333333 | AB8: 1
A9: Federated ID | B9: jwomack@montrose-env.com | C9: montrose-env.com | D9: Jwomack@montrose-env.com | E9: Jake | F9: Womack | G9: US | H9: 12B8266163DAA9CB0A495C28@038d2aa263c9deeb495fea.e | I9: Default Acrobat Pro configuration | N9: USA - Stack - Seattle - Operations | S9: Acrobat Pro (VIPMP - 99C0A3088A102BD9CB4A) | V9: CC001 | W9: USA - Stack - Seattle - Operations | X9: =IFERROR(VLOOKUP(I9,'Rate Sheet'!$D:$F,3,FALSE),0) -> 14.333333 | Y9: =IFERROR(VLOOKUP(J9,'Rate Sheet'!$D:$F,3,FALSE),0) -> 0 | Z9: =IFERROR(VLOOKUP(K9,'Rate Sheet'!$D:$F,3,FALSE),0) -> 0 | AA9: =SUM(X9:Z9) -> 14.333333 | AB9: 1
A10: Federated ID | B10: mlibman@montrose-env.com | C10: montrose-env.com | D10: mlibman@montrose-env.com | E10: Matt | F10: Libman | G10: US | H10: 3DC925EA63DBECBB0A495FA3@038d2aa263c9deeb495fea.e | I10: Default Acrobat Pro configuration | N10: USA - Stack - Chicago - G&A | S10: Acrobat Pro (VIPMP - 99C0A3088A102BD9CB4A) | V10: CC020 | W10: USA - Stack - Chicago - G&A | X10: =IFERROR(VLOOKUP(I10,'Rate Sheet'!$D:$F,3,FALSE),0) -> 14.333333 | Y10: =IFERROR(VLOOKUP(J10,'Rate Sheet'!$D:$F,3,FALSE),0) -> 0 | Z10: =IFERROR(VLOOKUP(K10,'Rate Sheet'!$D:$F,3,FALSE),0) -> 0 | AA10: =SUM(X10:Z10) -> 14.333333 | AB10: 1
A11: Federated ID | B11: kacyoung@montrose-env.com | C11: montrose-env.com | D11: kacyoung@montrose-env.com | E11: Katie | F11: Young | G11: US | H11: 4AF7245863DC2D0E0A495EBD@038d2aa263c9deeb495fea.e | I11: Default Acrobat Standard DC configuration | N11: USA - Environmental Consulting - Tampa - Operations | S11: Acrobat Standard DC (VIPMP - 99C0A3088A102BD9CB4A) | V11: CC112 | W11: USA - Consulting - Tampa - Operations | X11: =IFERROR(VLOOKUP(I11,'Rate Sheet'!$D:$F,3,FALSE),0) -> 8.6983333 | Y11: =IFERROR(VLOOKUP(J11,'Rate Sheet'!$D:$F,3,FALSE),0) -> 0 | Z11: =IFERROR(VLOOKUP(K11,'Rate Sheet'!$D:$F,3,FALSE),0) -> 0 | AA11: =SUM(X11:Z11) -> 8.6983333 | AB11: 1
A12: Federated ID | B12: kesmith@montrose-env.com | C12: montrose-env.com | D12: kesmith@montrose-env.com | E12: Kenneth | F12: Smith | G12: US | H12: DEE6260A63E163DC0A495C48@038d2aa263c9deeb495fea.e | I12: Default Acrobat Pro configuration | N12: USA - Environmental Consulting - Robbinsville - G&A | S12: Acrobat Pro (VIPMP - 99C0A3088A102BD9CB4A) | V12: CC116 | W12: USA - Consulting - Robbinsville - G&A | X12: =IFERROR(VLOOKUP(I12,'Rate Sheet'!$D:$F,3,FALSE),0) -> 14.333333 | Y12: =IFERROR(VLOOKUP(J12,'Rate Sheet'!$D:$F,3,FALSE),0) -> 0 | Z12: =IFERROR(VLOOKUP(K12,'Rate Sheet'!$D:$F,3,FALSE),0) -> 0 | AA12: =SUM(X12:Z12) -> 14.333333 | AB12: 1
A13: Federated ID | B13: schiew@montrose-env.com | C13: montrose-env.com | D13: schiew@montrose-env.com | E13: Sin Hoi | F13: Chiew | G13: US | H13: 05E72A4E63E45DD20A495E57@038d2aa263c9deeb495fea.e | I13: Default Acrobat Pro configuration | N13: USA - Stack - Cleveland - Operations | S13: Acrobat Pro (VIPMP - 99C0A3088A102BD9CB4A) | V13: CC022 | W13: USA - Stack - Cleveland - Operations | X13: =IFERROR(VLOOKUP(I13,'Rate Sheet'!$D:$F,3,FALSE),0) -> 14.333333 | Y13: =IFERROR(VLOOKUP(J13,'Rate Sheet'!$D:$F,3,FALSE),0) -> 0 | Z13: =IFERROR(VLOOKUP(K13,'Rate Sheet'!$D:$F,3,FALSE),0) -> 0 | AA13: =SUM(X13:Z13) -> 14.333333 | AB13: 1
A14: Federated ID | B14: tjscuthbertson@montrose-env.com | C14: montrose-env.com | D14: tjscuthbertson@montrose-env.com | E14: Thomas | F14: Cuthbertson | G14: US | H14: 6F2728E563E706EB0A495FBA@038d2aa263c9deeb495fea.e | I14: Default Acrobat Pro configuration | N14: CAN - OGI - Operations | S14: Acrobat Pro (VIPMP - 99C0A3088A102BD9CB4A) | V14: CC061 | W14: CAN - OGI - Operations | X14: =IFERROR(VLOOKUP(I14,'Rate Sheet'!$D:$F,3,FALSE),0) -> 14.333333 | Y14: =IFERROR(VLOOKUP(J14,'Rate Sheet'!$D:$F,3,FALSE),0) -> 0 | Z14: =IFERROR(VLOOKUP(K14,'Rate Sheet'!$D:$F,3,FALSE),0) -> 0 | AA14: =SUM(X14:Z14) -> 14.333333 | AB14: 1
A15: Federated ID | B15: matandukar@ect2.com | C15: ect2.com | D15: matandukar@ect2.com | E15: Madan | F15: Tandukar | G15: US | H15: C0FB295363EA5C4C0A495E94@038d2aa263c9deeb495fea.e | I15: Default All Apps plan configuration | N15: USA - ECT2 - Operations | S15: All Apps plan (VIPMP - 99C0A3088A102BD9CB4A) | V15: CC135 | W15: USA - ECT2 - Operations | X15: =IFERROR(VLOOKUP(I15,'Rate Sheet'!$D:$F,3,FALSE),0) -> 82.24 | Y15: =IFERROR(VLOOKUP(J15,'Rate Sheet'!$D:$F,3,FALSE),0) -> 0 | Z15: =IFERROR(VLOOKUP(K15,'Rate Sheet'!$D:$F,3,FALSE),0) -> 0 | AA15: =SUM(X15:Z15) -> 82.24 | AB15: 1
A16: Federated ID | B16: djensen@montrose-env.com | C16: montrose-env.com | D16: djensen@montrose-env.com | E16: Dan | F16: Jensen | G16: US | H16: BF9E29CF63EA60350A495EB3@c67c263163d83b8d0a495c06 | I16: Default Acrobat Pro configuration | N16: USA - Corp - Enterprise Solution Services | S16: Acrobat Pro (VIPMP - 99C0A3088A102BD9CB4A) | V16: CC466 | W16: USA - Corp - Digital Engagement | X16: =IFERROR(VLOOKUP(I16,'Rate Sheet'!$D:$F,3,FALSE),0) -> 14.333333 | Y16: =IFERROR(VLOOKUP(J16,'Rate Sheet'!$D:$F,3,FALSE),0) -> 0 | Z16: =IFERROR(VLOOKUP(K16,'Rate Sheet'!$D:$F,3,FALSE),0) -> 0 | AA16: =SUM(X16:Z16) -> 14.333333 | AB16: 1
A17: Federated ID | B17: jruggaber@montrose-env.com | C17: montrose-env.com | D17: jruggaber@montrose-env.com | E17: Joel | F17: Ruggaber | G17: US | H17: 1321268363ECFFB90A495FC6@038d2aa263c9deeb495fea.e | I17: Default Acrobat Pro configuration | N17: USA - Stack - Chicago - Operations | S17: Acrobat Pro (VIPMP - 99C0A3088A102BD9CB4A) | V17: CC019 | W17: USA - Stack - Chicago - Operations | X17: =IFERROR(VLOOKUP(I17,'Rate Sheet'!$D:$F,3,FALSE),0) -> 14.333333 | Y17: =IFERROR(VLOOKUP(J17,'Rate Sheet'!$D:$F,3,FALSE),0) -> 0 | Z17: =IFERROR(VLOOKUP(K17,'Rate Sheet'!$D:$F,3,FALSE),0) -> 0 | AA17: =SUM(X17:Z17) -> 14.333333 | AB17: 1
A18: Federated ID | B18: lford@montrose-env.com | C18: montrose-env.com | D18: lford@montrose-env.com | E18: Lee | F18: Ford | G18: US | H18: 493427C263EEA5BA0A495C9A@038d2aa263c9deeb495fea.e | I18: Default Acrobat Pro configuration | N18: USA - Environmental Consulting - Tampa - Sales & Marketing | S18: Acrobat Pro (VIPMP - 99C0A3088A102BD9CB4A) | V18: CC114 | W18: USA - Consulting - Tampa - Sales & Marketing | X18: =IFERROR(VLOOKUP(I18,'Rate Sheet'!$D:$F,3,FALSE),0) -> 14.333333 | Y18: =IFERROR(VLOOKUP(J18,'Rate Sheet'!$D:$F,3,FALSE),0) -> 0 | Z18: =IFERROR(VLOOKUP(K18,'Rate Sheet'!$D:$F,3,FALSE),0) -> 0 | AA18: =SUM(X18:Z18) -> 14.333333 | AB18: 1
A19: Federated ID | B19: caduncanson@montrose-env.com | C19: montrose-env.com | D19: caduncanson@montrose-env.com | E19: Cassie | F19: Duncanson-Cappe | G19: US | H19: BE58252263F3DD5B0A495EEF@038d2aa263c9deeb495fea.e | I19: Default Acrobat Pro configuration | J19: Default InDesign configuration | N19: USA - Corp - Sales | S19: Acrobat Pro (VIPMP - 99C0A3088A102BD9CB4A),InDesign (VIPMP - 99C0A3088A102BD9CB4A) | V19: CC267 | W19: USA - Corp - Sales | X19: =IFERROR(VLOOKUP(I19,'Rate Sheet'!$D:$F,3,FALSE),0) -> 14.333333 | Y19: =IFERROR(VLOOKUP(J19,'Rate Sheet'!$D:$F,3,FALSE),0) -> 35.979167 | Z19: =IFERROR(VLOOKUP(K19,'Rate Sheet'!$D:$F,3,FALSE),0) -> 0 | AA19: =SUM(X19:Z19) -> 50.3125 | AB19: 1
A20: Federated ID | B20: wewang@montrose-env.com | C20: montrose-env.com | D20: wewang@montrose-env.com | E20: Wei | F20: Wang | G20: US | H20: E0D0266B63F4EF010A495E6F@038d2aa263c9deeb495fea.e | N20: CAN - OGI - Operations | X20: =IFERROR(VLOOKUP(I20,'Rate Sheet'!$D:$F,3,FALSE),0) -> 0 | Y20: =IFERROR(VLOOKUP(J20,'Rate Sheet'!$D:$F,3,FALSE),0) -> 0 | Z20: =IFERROR(VLOOKUP(K20,'Rate Sheet'!$D:$F,3,FALSE),0) -> 0 | AA20: =SUM(X20:Z20) -> 0
A21: Federated ID | B21: dakempisty@ect2.com | C21: ect2.com | D21: dakempisty@ect2.com | E21: David | F21: Kempisty | G21: US | H21: 390E291C63F6DE4E0A495C71@038d2aa263c9deeb495fea.e | I21: Default Acrobat Pro configuration | N21: USA - Corp - R&D | S21: Acrobat Pro (VIPMP - 99C0A3088A102BD9CB4A) | V21: CC251 | W21: USA - Corp - R&D | X21: =IFERROR(VLOOKUP(I21,'Rate Sheet'!$D:$F,3,FALSE),0) -> 14.333333 | Y21: =IFERROR(VLOOKUP(J21,'Rate Sheet'!$D:$F,3,FALSE),0) -> 0 | Z21: =IFERROR(VLOOKUP(K21,'Rate Sheet'!$D:$F,3,FALSE),0) -> 0 | AA21: =SUM(X21:Z21) -> 14.333333 | AB21: 1
A22: Federated ID | B22: adoubleday@montrose-env.com | C22: montrose-env.com | D22: adoubleday@montrose-env.com | E22: Adam | F22: Doubleday | G22: US | H22: 6F4527D963F8FA290A495ED7@038d2aa263c9deeb495fea.e | I22: Default Acrobat Pro configuration | N22: USA - Environmental Consulting - Valley Forge - Operations | S22: Acrobat Pro (VIPMP - 99C0A3088A102BD9CB4A) | V22: CC300 | W22: USA - Consulting - Operational Support - Logistics & Variable Staffing | X22: =IFERROR(VLOOKUP(I22,'Rate Sheet'!$D:$F,3,FALSE),0) -> 14.333333 | Y22: =IFERROR(VLOOKUP(J22,'Rate Sheet'!$D:$F,3,FALSE),0) -> 0 | Z22: =IFERROR(VLOOKUP(K22,'Rate Sheet'!$D:$F,3,FALSE),0) -> 0 | AA22: =SUM(X22:Z22) -> 14.333333 | AB22: 1
A23: Federated ID | B23: jbolakas@montrose-env.com | C23: montrose-env.com | D23: jbolakas@montrose-env.com | E23: John | F23: Bolakas | G23: US | H23: 428E27CC63FCC7C10A495E58@038d2aa263c9deeb495fea.e | I23: Default Acrobat Pro configuration | N23: USA - Environmental Consulting - Charlottesville - Operations | S23: Acrobat Pro (VIPMP - 99C0A3088A102BD9CB4A) | V23: CC291 | W23: USA - Consulting - OH - Sales | X23: =IFERROR(VLOOKUP(I23,'Rate Sheet'!$D:$F,3,FALSE),0) -> 14.333333 | Y23: =IFERROR(VLOOKUP(J23,'Rate Sheet'!$D:$F,3,FALSE),0) -> 0 | Z23: =IFERROR(VLOOKUP(K23,'Rate Sheet'!$D:$F,3,FALSE),0) -> 0 | AA23: =SUM(X23:Z23) -> 14.333333 | AB23: 1
A24: Federated ID | B24: jorounsaville@montrose-env.com | C24: montrose-env.com | D24: jorounsaville@montrose-env.com | E24: Joseph | F24: Rounsaville | G24: US | H24: 6B4F28FB63FE1DDD0A495EDD@038d2aa263c9deeb495fea.e | N24: USA - Remediation - Northeast - Operations | X24: =IFERROR(VLOOKUP(I24,'Rate Sheet'!$D:$F,3,FALSE),0) -> 0 | Y24: =IFERROR(VLOOKUP(J24,'Rate Sheet'!$D:$F,3,FALSE),0) -> 0 | Z24: =IFERROR(VLOOKUP(K24,'Rate Sheet'!$D:$F,3,FALSE),0) -> 0 | AA24: =SUM(X24:Z24) -> 0
A25: Federated ID | B25: tanelson@montrose-env.com | C25: montrose-env.com | D25: tanelson@montrose-env.com | E25: Taylor | F25: Nelson | G25: US | H25: 937C2A8063FF9B650A495E11@038d2aa263c9deeb495fea.e | I25: Default Acrobat Pro configuration | N25: USA - Corp - Marketing | S25: Acrobat Pro (VIPMP - 99C0A3088A102BD9CB4A) | V25: CC037 | W25: USA - Air Testing - OH - Marketing | X25: =IFERROR(VLOOKUP(I25,'Rate Sheet'!$D:$F,3,FALSE),0) -> 14.333333 | Y25: =IFERROR(VLOOKUP(J25,'Rate Sheet'!$D:$F,3,FALSE),0) -> 0 | Z25: =IFERROR(VLOOKUP(K25,'Rate Sheet'!$D:$F,3,FALSE),0) -> 0 | AA25: =SUM(X25:Z25) -> 14.333333 | AB25: 1
A26: Federated ID | B26: mamatelski@montrose-env.com | C26: montrose-env.com | D26: mamatelski@montrose-env.com | E26: Marie | F26: Matelski | G26: US | H26: 9C882AB963FFCA5E0A495FDB@038d2aa263c9deeb495fea.e | N26: USA - Environmental Consulting - Environmental Intelligence - Operations | X26: =IFERROR(VLOOKUP(I26,'Rate Sheet'!$D:$F,3,FALSE),0) -> 0 | Y26: =IFERROR(VLOOKUP(J26,'Rate Sheet'!$D:$F,3,FALSE),0) -> 0 | Z26: =IFERROR(VLOOKUP(K26,'Rate Sheet'!$D:$F,3,FALSE),0) -> 0 | AA26: =SUM(X26:Z26) -> 0
A27: Federated ID | B27: thlyons@montrose-env.com | C27: montrose-env.com | D27: thlyons@montrose-env.com | E27: Thomas | F27: Lyons | G27: US | H27: B9C22AB96400E0E30A495FDB@038d2aa263c9deeb495fea.e | N27: USA - Environmental Consulting - Orlando - Operations,USA - Stack - Northeast - Operations | X27: =IFERROR(VLOOKUP(I27,'Rate Sheet'!$D:$F,3,FALSE),0) -> 0 | Y27: =IFERROR(VLOOKUP(J27,'Rate Sheet'!$D:$F,3,FALSE),0) -> 0 | Z27: =IFERROR(VLOOKUP(K27,'Rate Sheet'!$D:$F,3,FALSE),0) -> 0 | AA27: =SUM(X27:Z27) -> 0
A28: Federated ID | B28: swoodard@ect2.com | C28: ect2.com | D28: SWoodard@ect2.com | E28: Steven | F28: Woodard | G28: US | H28: D93127A86401F4190A495FBD@038d2aa263c9deeb495fea.e | I28: Default Acrobat Pro configuration | N28: USA - Corp - R&D | S28: Acrobat Pro (VIPMP - 99C0A3088A102BD9CB4A) | V28: CC251 | W28: USA - Corp - R&D | X28: =IFERROR(VLOOKUP(I28,'Rate Sheet'!$D:$F,3,FALSE),0) -> 14.333333 | Y28: =IFERROR(VLOOKUP(J28,'Rate Sheet'!$D:$F,3,FALSE),0) -> 0 | Z28: =IFERROR(VLOOKUP(K28,'Rate Sheet'!$D:$F,3,FALSE),0) -> 0 | AA28: =SUM(X28:Z28) -> 14.333333 | AB28: 1
A29: Federated ID | B29: sweeks@montrose-env.com | C29: montrose-env.com | D29: sweeks@montrose-env.com | E29: Stina | F29: Weeks | G29: US | H29: D8B128FF640234940A495EE6@038d2aa263c9deeb495fea.e | I29: Default Acrobat Pro configuration | N29: USA - Stack - Antioch - Operations | S29: Acrobat Pro (VIPMP - 99C0A3088A102BD9CB4A) | V29: CC004 | W29: USA - Stack - Antioch - Operations | X29: =IFERROR(VLOOKUP(I29,'Rate Sheet'!$D:$F,3,FALSE),0) -> 14.333333 | Y29: =IFERROR(VLOOKUP(J29,'Rate Sheet'!$D:$F,3,FALSE),0) -> 0 | Z29: =IFERROR(VLOOKUP(K29,'Rate Sheet'!$D:$F,3,FALSE),0) -> 0 | AA29: =SUM(X29:Z29) -> 14.333333 | AB29: 1
A30: Federated ID | B30: domatthys@montrose-env.com | C30: montrose-env.com | D30: domatthys@montrose-env.com | E30: Douglas | F30: Matthys | G30: US | H30: 294A2AA16405ECEF0A495CA0@038d2aa263c9deeb495fea.e | N30: USA - Environmental Consulting OH - G&A | X30: =IFERROR(VLOOKUP(I30,'Rate Sheet'!$D:$F,3,FALSE),0) -> 0 | Y30: =IFERROR(VLOOKUP(J30,'Rate Sheet'!$D:$F,3,FALSE),0) -> 0 | Z30: =IFERROR(VLOOKUP(K30,'Rate Sheet'!$D:$F,3,FALSE),0) -> 0 | AA30: =SUM(X30:Z30) -> 0
A31: Federated ID | B31: deanna.yates@enthalpy.com | C31: enthalpy.com | D31: deanna.yates@enthalpy.com | E31: Deanna | F31: Yates | G31: US | H31: 272025796405F90C0A495C7B@038d2aa263c9deeb495fea.e | I31: Default Acrobat Pro configuration | N31: USA - Labs - OH - HR | S31: Acrobat Pro (VIPMP - 99C0A3088A102BD9CB4A) | V31: CC210 | W31: USA - Lab Testing - OH - HR | X31: =IFERROR(VLOOKUP(I31,'Rate Sheet'!$D:$F,3,FALSE),0) -> 14.333333 | Y31: =IFERROR(VLOOKUP(J31,'Rate Sheet'!$D:$F,3,FALSE),0) -> 0 | Z31: =IFERROR(VLOOKUP(K31,'Rate Sheet'!$D:$F,3,FALSE),0) -> 0 | AA31: =SUM(X31:Z31) -> 14.333333 | AB31: 1
A32: Federated ID | B32: mchowsanitphon@montrose-env.com | C32: montrose-env.com | D32: mchowsanitphon@montrose-env.com | E32: Michael | F32: Chowsanitphon | G32: US | H32: 3694253E640672EC0A495FB4@038d2aa263c9deeb495fea.e | I32: Default Acrobat Standard DC configuration | N32: USA - Stack - Santa Ana - Operations | S32: Acrobat Standard DC (VIPMP - 99C0A3088A102BD9CB4A) | V32: CC007 | W32: USA - Stack - Santa Ana - Operations | X32: =IFERROR(VLOOKUP(I32,'Rate Sheet'!$D:$F,3,FALSE),0) -> 8.6983333 | Y32: =IFERROR(VLOOKUP(J32,'Rate Sheet'!$D:$F,3,FALSE),0) -> 0 | Z32: =IFERROR(VLOOKUP(K32,'Rate Sheet'!$D:$F,3,FALSE),0) -> 0 | AA32: =SUM(X32:Z32) -> 8.6983333 | AB32: 1
A33: Federated ID | B33: wezhou@montrose-env.com | C33: montrose-env.com | D33: wezhou@montrose-env.com | E33: Wei | F33: Zhou | G33: US | H33: 42DD2991640B8D960A495FC1@038d2aa263c9deeb495fea.e | I33: Default Acrobat Pro configuration | N33: USA - Advisory Services - Chemistry - Operations | S33: Acrobat Pro (VIPMP - 99C0A3088A102BD9CB4A) | V33: CC324 | W33: USA - Advisory & Technical - Chemistry - Operations | X33: =IFERROR(VLOOKUP(I33,'Rate Sheet'!$D:$F,3,FALSE),0) -> 14.333333 | Y33: =IFERROR(VLOOKUP(J33,'Rate Sheet'!$D:$F,3,FALSE),0) -> 0 | Z33: =IFERROR(VLOOKUP(K33,'Rate Sheet'!$D:$F,3,FALSE),0) -> 0 | AA33: =SUM(X33:Z33) -> 14.333333 | AB33: 1
A34: Federated ID | B34: sarah.mack@enthalpy.com | C34: enthalpy.com | D34: sarah.mack@enthalpy.com | E34: Sarah | F34: Mack | G34: US | H34: 8D1A2A06640F74B40A495E6D@038d2aa263c9deeb495fea.e | I34: Default Acrobat Pro configuration | N34: USA - Labs - OH - Sales | S34: Acrobat Pro (VIPMP - 99C0A3088A102BD9CB4A) | V34: CC365 | W34: USA - Lab Testing - OH - Sales | X34: =IFERROR(VLOOKUP(I34,'Rate Sheet'!$D:$F,3,FALSE),0) -> 14.333333 | Y34: =IFERROR(VLOOKUP(J34,'Rate Sheet'!$D:$F,3,FALSE),0) -> 0 | Z34: =IFERROR(VLOOKUP(K34,'Rate Sheet'!$D:$F,3,FALSE),0) -> 0 | AA34: =SUM(X34:Z34) -> 14.333333 | AB34: 1
A35: Federated ID | B35: dacoles@montrose-env.com | C35: montrose-env.com | D35: dacoles@montrose-env.com | E35: Danielle | F35: Coles | G35: US | H35: 91C32A52640FE28A0A495F8E@038d2aa263c9deeb495fea.e | I35: Default Acrobat Pro configuration | N35: USA - Advisory Services - Chemistry - Operations | S35: Acrobat Pro (VIPMP - 99C0A3088A102BD9CB4A) | V35: CC324 | W35: USA - Advisory & Technical - Chemistry - Operations | X35: =IFERROR(VLOOKUP(I35,'Rate Sheet'!$D:$F,3,FALSE),0) -> 14.333333 | Y35: =IFERROR(VLOOKUP(J35,'Rate Sheet'!$D:$F,3,FALSE),0) -> 0 | Z35: =IFERROR(VLOOKUP(K35,'Rate Sheet'!$D:$F,3,FALSE),0) -> 0 | AA35: =SUM(X35:Z35) -> 14.333333 | AB35: 1
A36: Federated ID | B36: wayneglenny@montrose-env.com | C36: montrose-env.com | D36: wayneglenny@montrose-env.com | E36: Wayne | F36: Glenny | G36: US | H36: A8BE2A2E6410C9430A495FAE@038d2aa263c9deeb495fea.e | I36: Default Acrobat Pro configuration | N36: USA - Environmental Consulting - Environmental Intelligence - Operations | S36: Acrobat Pro (VIPMP - 99C0A3088A102BD9CB4A) | V36: CC272 | W36: USA - Consulting - Environmental Intelligence - Operations | X36: =IFERROR(VLOOKUP(I36,'Rate Sheet'!$D:$F,3,FALSE),0) -> 14.333333 | Y36: =IFERROR(VLOOKUP(J36,'Rate Sheet'!$D:$F,3,FALSE),0) -> 0 | Z36: =IFERROR(VLOOKUP(K36,'Rate Sheet'!$D:$F,3,FALSE),0) -> 0 | AA36: =SUM(X36:Z36) -> 14.333333 | AB36: 1
A37: Federated ID | B37: chwymore@montrose-env.com | C37: montrose-env.com | D37: chwymore@montrose-env.com | E37: Christopher | F37: Wymore | G37: US | H37: CDCE29ED6411EE4A0A495C53@038d2aa263c9deeb495fea.e | I37: Default Acrobat Pro configuration | N37: USA - Stack - Antioch - Operations | S37: Acrobat Pro (VIPMP - 99C0A3088A102BD9CB4A) | V37: CC004 | W37: USA - Stack - Antioch - Operations | X37: =IFERROR(VLOOKUP(I37,'Rate Sheet'!$D:$F,3,FALSE),0) -> 14.333333 | Y37: =IFERROR(VLOOKUP(J37,'Rate Sheet'!$D:$F,3,FALSE),0) -> 0 | Z37: =IFERROR(VLOOKUP(K37,'Rate Sheet'!$D:$F,3,FALSE),0) -> 0 | AA37: =SUM(X37:Z37) -> 14.333333 | AB37: 1
A38: Federated ID | B38: amnilles@montrose-env.com | C38: montrose-env.com | D38: amnilles@montrose-env.com | E38: Amanda | F38: Nilles | G38: US | H38: FCA72A6F641362B70A495F8A@038d2aa263c9deeb495fea.e | I38: Default Acrobat Standard DC configuration | N38: USA - Stack - OH - G&A | S38: Acrobat Standard DC (VIPMP - 99C0A3088A102BD9CB4A) | V38: CC219 | W38: USA - Stack - Power Start-Ups - Operations | X38: =IFERROR(VLOOKUP(I38,'Rate Sheet'!$D:$F,3,FALSE),0) -> 8.6983333 | Y38: =IFERROR(VLOOKUP(J38,'Rate Sheet'!$D:$F,3,FALSE),0) -> 0 | Z38: =IFERROR(VLOOKUP(K38,'Rate Sheet'!$D:$F,3,FALSE),0) -> 0 | AA38: =SUM(X38:Z38) -> 8.6983333 | AB38: 1
A39: Federated ID | B39: gamorales@montrose-env.com | C39: montrose-env.com | D39: gamorales@montrose-env.com | E39: Gabriel | F39: Morales | G39: US | H39: 02812A46641384A90A495C83@038d2aa263c9deeb495fea.e | L39: System | N39: USA - Corp - IT | X39: =IFERROR(VLOOKUP(I39,'Rate Sheet'!$D:$F,3,FALSE),0) -> 0 | Y39: =IFERROR(VLOOKUP(J39,'Rate Sheet'!$D:$F,3,FALSE),0) -> 0 | Z39: =IFERROR(VLOOKUP(K39,'Rate Sheet'!$D:$F,3,FALSE),0) -> 0 | AA39: =SUM(X39:Z39) -> 0
A40: Federated ID | B40: memercer@montrose-env.com | C40: montrose-env.com | D40: memercer@montrose-env.com | E40: Melissa | F40: Mercer | G40: US | H40: 257A2A6F6414B22A0A495F8A@038d2aa263c9deeb495fea.e | I40: Default Acrobat Pro configuration | N40: CAN - OGI - Operations | S40: Acrobat Pro (VIPMP - 99C0A3088A102BD9CB4A) | V40: CC061 | W40: CAN - OGI - Operations | X40: =IFERROR(VLOOKUP(I40,'Rate Sheet'!$D:$F,3,FALSE),0) -> 14.333333 | Y40: =IFERROR(VLOOKUP(J40,'Rate Sheet'!$D:$F,3,FALSE),0) -> 0 | Z40: =IFERROR(VLOOKUP(K40,'Rate Sheet'!$D:$F,3,FALSE),0) -> 0 | AA40: =SUM(X40:Z40) -> 14.333333 | AB40: 1
...

Sheet Rate Sheet
D7: Type of licenses | E7: annual rate | F7: monthly rate
D8: Default Acrobat Pro configuration | E8: 172 | F8: =+E8/12 -> 14.333333
D9: Default Adobe Captivate configuration | E9: 334.75 | F9: =+E9/12 -> 27.895833
D10: Default InDesign configuration | E10: 431.75 | F10: =+E10/12 -> 35.979167
D11: Default Illustrator configuration | E11: 436.29 | F11: =+E11/12 -> 36.3575
D12: Default Photoshop configuration | E12: 418.485 | F12: =+E12/12 -> 34.87375
C13: Default Photoshop - Edition 4 configuration | G13: pending confirmation if these are the same as the respective license
D14: Default Premiere Pro configuration | E14: 348.74 | F14: =+E14/12 -> 29.061667
D15: Default Acrobat Standard DC configuration | E15: 104.38 | F15: =+E15/12 -> 8.6983333
D16: Default All Apps plan configuration | E16: 986.88 | F16: =+E16/12 -> 82.24
C17: Default All Apps - Edition 4 configuration | G17: pending confirmation if these are the same as the respective license

Sheet Adobe users
A1: Identity Type | B1: Username | C1: Domain | D1: Email | E1: First Name | F1: Last Name | G1: Country Code | H1: ID | I1: Product Configurations | J1: Admin Roles | K1: Product Configurations Administered | L1: User Groups | M1: User Groups Administered | N1: Products Administered | O1: Contracts Administered | P1: Team Products | Q1: Enterprise Products | R1: Developer Access | S1: Auto Assigned Products
A2: Adobe ID | B2: mcarlin@montrose-env.com | C2: montrose-env.com | D2: mcarlin@montrose-env.com | E2: Mark | F2: Carlin | G2: US | H2: 038E2AA263C9DEEB0A495FEA@038d2aa263c9deeb495fea.e | J2: System | L2: USA - Corp - IT
A3: Adobe ID | B3: grant.wicker@enthalpy.com | C3: enthalpy.com | D3: grant.wicker@enthalpy.com | E3: Grant | F3: Wicker | G3: US | H3: 04172ACB63C9DF460A495E05@038d2aa263c9deeb495fea.e | L3: USA - Corp - IT
A4: Federated ID | B4: stescamilla@montrose-env.com | C4: montrose-env.com | D4: stescamilla@montrose-env.com | E4: Stacey | F4: Escamilla | G4: US | H4: C7E825EB63D846A50A495C5B@038d2aa263c9deeb495fea.e | L4: USA - Environmental Consulting - Environmental Intelligence - Operations
A5: Federated ID | B5: mcarlinadmin@montrose-env.com | C5: montrose-env.com | D5: mcarlinadmin@montrose-env.com | E5: Mark | F5: Carlin Admin | G5: US | H5: C5DE265363D849620A495FDA@038d2aa263c9deeb495fea.e | J5: System | L5: USA - Corp - IT
A6: Federated ID | B6: sbagchi@montrose-env.com | C6: montrose-env.com | D6: sbagchi@montrose-env.com | E6: Sohini | F6: Bagchi | G6: US | H6: C67F262A63D866EF0A495CA0@038d2aa263c9deeb495fea.e | I6: Default Acrobat Pro configuration | L6: USA - Environmental Consulting - Santa Ana (Rem) - Operations | Q6: Acrobat Pro (VIPMP - 99C0A3088A102BD9CB4A)
A7: Federated ID | B7: lwork@montrose-env.com | C7: montrose-env.com | D7: lwork@montrose-env.com | E7: Lydia | F7: Work | G7: US | H7: 08EB268D63DA6A030A495FB1@038d2aa263c9deeb495fea.e | I7: Default Acrobat Pro configuration | L7: USA - Environmental Consulting - Valley Forge - Operations | Q7: Acrobat Pro (VIPMP - 99C0A3088A102BD9CB4A)
A8: Federated ID | B8: ligordon@montrose-env.com | C8: montrose-env.com | D8: ligordon@montrose-env.com | E8: Lindsey | F8: Gordon | G8: US | H8: 1039261B63DA8F350A495FED@038d2aa263c9deeb495fea.e | I8: Default Acrobat Pro configuration | L8: USA - Environmental Consulting - Environmental Intelligence - Operations | Q8: Acrobat Pro (VIPMP - 99C0A3088A102BD9CB4A)
A9: Federated ID | B9: jwomack@montrose-env.com | C9: montrose-env.com | D9: Jwomack@montrose-env.com | E9: Jake | F9: Womack | G9: US | H9: 12B8266163DAA9CB0A495C28@038d2aa263c9deeb495fea.e | I9: Default Acrobat Pro configuration | L9: USA - Stack - Seattle - Operations | Q9: Acrobat Pro (VIPMP - 99C0A3088A102BD9CB4A)
A10: Federated ID | B10: mlibman@montrose-env.com | C10: montrose-env.com | D10: mlibman@montrose-env.com | E10: Matt | F10: Libman | G10: US | H10: 3DC925EA63DBECBB0A495FA3@038d2aa263c9deeb495fea.e | I10: Default Acrobat Pro configuration | L10: USA - Stack - Chicago - G&A | Q10: Acrobat Pro (VIPMP - 99C0A3088A102BD9CB4A)
A11: Federated ID | B11: kacyoung@montrose-env.com | C11: montrose-env.com | D11: kacyoung@montrose-env.com | E11: Katie | F11: Young | G11: US | H11: 4AF7245863DC2D0E0A495EBD@038d2aa263c9deeb495fea.e | I11: Default Acrobat Standard DC configuration | L11: USA - Environmental Consulting - Tampa - Operations | Q11: Acrobat Standard DC (VIPMP - 99C0A3088A102BD9CB4A)
A12: Federated ID | B12: kesmith@montrose-env.com | C12: montrose-env.com | D12: kesmith@montrose-env.com | E12: Kenneth | F12: Smith | G12: US | H12: DEE6260A63E163DC0A495C48@038d2aa263c9deeb495fea.e | I12: Default Acrobat Pro configuration | L12: USA - Environmental Consulting - Robbinsville - G&A | Q12: Acrobat Pro (VIPMP - 99C0A3088A102BD9CB4A)
A13: Federated ID | B13: schiew@montrose-env.com | C13: montrose-env.com | D13: schiew@montrose-env.com | E13: Sin Hoi | F13: Chiew | G13: US | H13: 05E72A4E63E45DD20A495E57@038d2aa263c9deeb495fea.e | I13: Default Acrobat Pro configuration | L13: USA - Stack - Cleveland - Operations | Q13: Acrobat Pro (VIPMP - 99C0A3088A102BD9CB4A)
A14: Federated ID | B14: tjscuthbertson@montrose-env.com | C14: montrose-env.com | D14: tjscuthbertson@montrose-env.com | E14: Thomas | F14: Cuthbertson | G14: US | H14: 6F2728E563E706EB0A495FBA@038d2aa263c9deeb495fea.e | I14: Default Acrobat Pro configuration | L14: CAN - OGI - Operations | Q14: Acrobat Pro (VIPMP - 99C0A3088A102BD9CB4A)
A15: Federated ID | B15: matandukar@ect2.com | C15: ect2.com | D15: matandukar@ect2.com | E15: Madan | F15: Tandukar | G15: US | H15: C0FB295363EA5C4C0A495E94@038d2aa263c9deeb495fea.e | I15: Default All Apps plan configuration | L15: USA - ECT2 - Operations | Q15: All Apps plan (VIPMP - 99C0A3088A102BD9CB4A)
A16: Federated ID | B16: djensen@montrose-env.com | C16: montrose-env.com | D16: djensen@montrose-env.com | E16: Dan | F16: Jensen | G16: US | H16: BF9E29CF63EA60350A495EB3@c67c263163d83b8d0a495c06 | I16: Default Acrobat Pro configuration | L16: USA - Corp - Enterprise Solution Services | Q16: Acrobat Pro (VIPMP - 99C0A3088A102BD9CB4A)
A17: Federated ID | B17: jruggaber@montrose-env.com | C17: montrose-env.com | D17: jruggaber@montrose-env.com | E17: Joel | F17: Ruggaber | G17: US | H17: 1321268363ECFFB90A495FC6@038d2aa263c9deeb495fea.e | I17: Default Acrobat Pro configuration | L17: USA - Stack - Chicago - Operations | Q17: Acrobat Pro (VIPMP - 99C0A3088A102BD9CB4A)
... A19: Federated ID | B19: caduncanson@montrose-env.com | C19: montrose-env.com | D19: caduncanson@montrose-env.com | E19: Cassie | F19: Duncanson-Cappe | G19: US | H19: BE58252263F3DD5B0A495EEF@038d2aa263c9deeb495fea.e | I19: Default Acrobat Pro configuration,Default InDesign configuration | L19: USA - Corp - Sales | Q19: Acrobat Pro (VIPMP - 99C0A3088A102BD9CB4A),InDesign (VIPMP - 99C0A3088A102BD9CB4A)
A20: Federated ID | B20: wewang@montrose-env.com | C20: montrose-env.com | D20: wewang@montrose-env.com | E20: Wei | F20: Wang | G20: US | H20: E0D0266B63F4EF010A495E6F@038d2aa263c9deeb495fea.e | L20: CAN - OGI - Operations
A21: Federated ID | B21: dakempisty@ect2.com | C21: ect2.com | D21: dakempisty@ect2.com | E21: David | F21: Kempisty | G21: US | H21: 390E291C63F6DE4E0A495C71@038d2aa263c9deeb495fea.e | I21: Default Acrobat Pro configuration | L21: USA - Corp - R&D | Q21: Acrobat Pro (VIPMP - 99C0A3088A102BD9CB4A)
A22: Federated ID | B22: adoubleday@montrose-env.com | C22: montrose-env.com | D22: adoubleday@montrose-env.com | E22: Adam | F22: Doubleday | G22: US | H22: 6F4527D963F8FA290A495ED7@038d2aa263c9deeb495fea.e | I22: Default Acrobat Pro configuration | L22: USA - Environmental Consulting - Valley Forge - Operations | Q22: Acrobat Pro (VIPMP - 99C0A3088A102BD9CB4A)
A23: Federated ID | B23: jbolakas@montrose-env.com | C23: montrose-env.com | D23: jbolakas@montrose-env.com | E23: John | F23: Bolakas | G23: US | H23: 428E27CC63FCC7C10A495E58@038d2aa263c9deeb495fea.e | I23: Default Acrobat Pro configuration | L23: USA - Environmental Consulting - Charlottesville - Operations | Q23: Acrobat Pro (VIPMP - 99C0A3088A102BD9CB4A)
A24: Federated ID | B24: jorounsaville@montrose-env.com | C24: montrose-env.com | D24: jorounsaville@montrose-env.com | E24: Joseph | F24: Rounsaville | G24: US | H24: 6B4F28FB63FE1DDD0A495EDD@038d2aa263c9deeb495fea.e | L24: USA - Remediation - Northeast - Operations
A25: Federated ID | B25: tanelson@montrose-env.com | C25: montrose-env.com | D25: tanelson@montrose-env.com | E25: Taylor | F25: Nelson | G25: US | H25: 937C2A8063FF9B650A495E11@038d2aa263c9deeb495fea.e | I25: Default Acrobat Pro configuration | L25: USA - Corp - Marketing | Q25: Acrobat Pro (VIPMP - 99C0A3088A102BD9CB4A)
A26: Federated ID | B26: mamatelski@montrose-env.com | C26: montrose-env.com | D26: mamatelski@montrose-env.com | E26: Marie | F26: Matelski | G26: US | H26: 9C882AB963FFCA5E0A495FDB@038d2aa263c9deeb495fea.e | L26: USA - Environmental Consulting - Environmental Intelligence - Operations
A27: Federated ID | B27: thlyons@montrose-env.com | C27: montrose-env.com | D27: thlyons@montrose-env.com | E27: Thomas | F27: Lyons | G27: US | H27: B9C22AB96400E0E30A495FDB@038d2aa263c9deeb495fea.e | L27: USA - Environmental Consulting - Orlando - Operations,USA - Stack - Northeast - Operations
A28: Federated ID | B28: swoodard@ect2.com | C28: ect2.com | D28: SWoodard@ect2.com | E28: Steven | F28: Woodard | G28: US | H28: D93127A86401F4190A495FBD@038d2aa263c9deeb495fea.e | I28: Default Acrobat Pro configuration | L28: USA - Corp - R&D | Q28: Acrobat Pro (VIPMP - 99C0A3088A102BD9CB4A)
A29: Federated ID | B29: sweeks@montrose-env.com | C29: montrose-env.com | D29: sweeks@montrose-env.com | E29: Stina | F29: Weeks | G29: US | H29: D8B128FF640234940A495EE6@038d2aa263c9deeb495fea.e | I29: Default Acrobat Pro configuration | L29: USA - Stack - Antioch - Operations | Q29: Acrobat Pro (VIPMP - 99C0A3088A102BD9CB4A)
A30: Federated ID | B30: domatthys@montrose-env.com | C30: montrose-env.com | D30: domatthys@montrose-env.com | E30: Douglas | F30: Matthys | G30: US | H30: 294A2AA16405ECEF0A495CA0@038d2aa263c9deeb495fea.e | L30: USA - Environmental Consulting OH - G&A
A31: Federated ID | B31: deanna.yates@enthalpy.com | C31: enthalpy.com | D31: deanna.yates@enthalpy.com | E31: Deanna | F31: Yates | G31: US | H31: 272025796405F90C0A495C7B@038d2aa263c9deeb495fea.e | I31: Default Acrobat Pro configuration | L31: USA - Labs - OH - HR | Q31: Acrobat Pro (VIPMP - 99C0A3088A102BD9CB4A)
A32: Federated ID | B32: mchowsanitphon@montrose-env.com | C32: montrose-env.com | D32: mchowsanitphon@montrose-env.com | E32: Michael | F32: Chowsanitphon | G32: US | H32: 3694253E640672EC0A495FB4@038d2aa263c9deeb495fea.e | I32: Default Acrobat Standard DC configuration | L32: USA - Stack - Santa Ana - Operations | Q32: Acrobat Standard DC (VIPMP - 99C0A3088A102BD9CB4A)
A33: Federated ID | B33: wezhou@montrose-env.com | C33: montrose-env.com | D33: wezhou@montrose-env.com | E33: Wei | F33: Zhou | G33: US | H33: 42DD2991640B8D960A495FC1@038d2aa263c9deeb495fea.e | I33: Default Acrobat Pro configuration | L33: USA - Advisory Services - Chemistry - Operations | Q33: Acrobat Pro (VIPMP - 99C0A3088A102BD9CB4A)
A34: Federated ID | B34: sarah.mack@enthalpy.com | C34: enthalpy.com | D34: sarah.mack@enthalpy.com | E34: Sarah | F34: Mack | G34: US | H34: 8D1A2A06640F74B40A495E6D@038d2aa263c9deeb495fea.e | I34: Default Acrobat Pro configuration | L34: USA - Labs - OH - Sales | Q34: Acrobat Pro (VIPMP - 99C0A3088A102BD9CB4A)
A35: Federated ID | B35: dacoles@montrose-env.com | C35: montrose-env.com | D35: dacoles@montrose-env.com | E35: Danielle | F35: Coles | G35: US | H35: 91C32A52640FE28A0A495F8E@038d2aa263c9deeb495fea.e | I35: Default Acrobat Pro configuration | L35: USA - Advisory Services - Chemistry - Operations | Q35: Acrobat Pro (VIPMP - 99C0A3088A102BD9CB4A)
A36: Federated ID | B36: wayneglenny@montrose-env.com | C36: montrose-env.com | D36: wayneglenny@montrose-env.com | E36: Wayne | F36: Glenny | G36: US | H36: A8BE2A2E6410C9430A495FAE@038d2aa263c9deeb495fea.e | I36: Default Acrobat Pro configuration | L36: USA - Environmental Consulting - Environmental Intelligence - Operations | Q36: Acrobat Pro (VIPMP - 99C0A3088A102BD9CB4A)
A37: Federated ID | B37: chwymore@montrose-env.com | C37: montrose-env.com | D37: chwymore@montrose-env.com | E37: Christopher | F37: Wymore | G37: US | H37: CDCE29ED6411EE4A0A495C53@038d2aa263c9deeb495fea.e | I37: Default Acrobat Pro configuration | L37: USA - Stack - Antioch - Operations | Q37: Acrobat Pro (VIPMP - 99C0A3088A102BD9CB4A)
A38: Federated ID | B38: amnilles@montrose-env.com | C38: montrose-env.com | D38: amnilles@montrose-env.com | E38: Amanda | F38: Nilles | G38: US | H38: FCA72A6F641362B70A495F8A@038d2aa263c9deeb495fea.e | I38: Default Acrobat Standard DC configuration | L38: USA - Stack - OH - G&A | Q38: Acrobat Standard DC (VIPMP - 99C0A3088A102BD9CB4A)
A39: Federated ID | B39: gamorales@montrose-env.com | C39: montrose-env.com | D39: gamorales@montrose-env.com | E39: Gabriel | F39: Morales | G39: US | H39: 02812A46641384A90A495C83@038d2aa263c9deeb495fea.e | J39: System | L39: USA - Corp - IT
A40: Federated ID | B40: memercer@montrose-env.com | C40: montrose-env.com | D40: memercer@montrose-env.com | E40: Melissa | F40: Mercer | G40: US | H40: 257A2A6F6414B22A0A495F8A@038d2aa263c9deeb495fea.e | I40: Default Acrobat Pro configuration | L40: CAN - OGI - Operations | Q40: Acrobat Pro (VIPMP - 99C0A3088A102BD9CB4A)
A41: Federated ID | B41: mesloan@montrose-env.com | C41: montrose-env.com | D41: mesloan@montrose-env.com | E41: Merritt | F41: Sloan | G41: US | H41: 5FFE2A386417554B0A495FF0@038d2aa263c9deeb495fea.e | I41: Default Acrobat Pro configuration | L41: USA - Advisory Services - Chemistry - Operations | Q41: Acrobat Pro (VIPMP - 99C0A3088A102BD9CB4A)
...
